Workbook

Sheet 统计概览
A2: 稳定币安全事件统计 | B2: 稳定币安全事件统计（v3.1） | C2: 稳定币安全事件统计（v3.1） | D2: 稳定币安全事件统计（v3.1） | E2: 稳定币安全事件统计（v3.1）
A3: 样本：108起事件；每起事件记录一个主要风险起点和一个主要风险性质。
A4: 风险起点 | B4: 总数 | C4: 继承 | D4: 重塑 | E4: 特有
A5: C_VS 价值支撑 | B5: =SUM(C5:E5) -> 14 | C5: =COUNTIFS('108案详情'!$H$5:$H$112,"C_VS",'108案详情'!$K$5:$K$112,"继承风险") -> 0 | D5: =COUNTIFS('108案详情'!$H$5:$H$112,"C_VS",'108案详情'!$K$5:$K$112,"重塑风险") -> 0 | E5: =COUNTIFS('108案详情'!$H$5:$H$112,"C_VS",'108案详情'!$K$5:$K$112,"稳定币特有风险") -> 14
A6: C_PR 协议规则 | B6: =SUM(C6:E6) -> 9 | C6: =COUNTIFS('108案详情'!$H$5:$H$112,"C_PR",'108案详情'!$K$5:$K$112,"继承风险") -> 3 | D6: =COUNTIFS('108案详情'!$H$5:$H$112,"C_PR",'108案详情'!$K$5:$K$112,"重塑风险") -> 6 | E6: =COUNTIFS('108案详情'!$H$5:$H$112,"C_PR",'108案详情'!$K$5:$K$112,"稳定币特有风险") -> 0
A7: C_CI 合约实现 | B7: =SUM(C7:E7) -> 20 | C7: =COUNTIFS('108案详情'!$H$5:$H$112,"C_CI",'108案详情'!$K$5:$K$112,"继承风险") -> 5 | D7: =COUNTIFS('108案详情'!$H$5:$H$112,"C_CI",'108案详情'!$K$5:$K$112,"重塑风险") -> 15 | E7: =COUNTIFS('108案详情'!$H$5:$H$112,"C_CI",'108案详情'!$K$5:$K$112,"稳定币特有风险") -> 0
A8: C_RD 运行依赖 | B8: =SUM(C8:E8) -> 8 | C8: =COUNTIFS('108案详情'!$H$5:$H$112,"C_RD",'108案详情'!$K$5:$K$112,"继承风险") -> 0 | D8: =COUNTIFS('108案详情'!$H$5:$H$112,"C_RD",'108案详情'!$K$5:$K$112,"重塑风险") -> 8 | E8: =COUNTIFS('108案详情'!$H$5:$H$112,"C_RD",'108案详情'!$K$5:$K$112,"稳定币特有风险") -> 0
A9: M_LI 流动性 | B9: =SUM(C9:E9) -> 5 | C9: =COUNTIFS('108案详情'!$H$5:$H$112,"M_LI",'108案详情'!$K$5:$K$112,"继承风险") -> 1 | D9: =COUNTIFS('108案详情'!$H$5:$H$112,"M_LI",'108案详情'!$K$5:$K$112,"重塑风险") -> 3 | E9: =COUNTIFS('108案详情'!$H$5:$H$112,"M_LI",'108案详情'!$K$5:$K$112,"稳定币特有风险") -> 1
A10: M_PR 锚定修复 | B10: =SUM(C10:E10) -> 3 | C10: =COUNTIFS('108案详情'!$H$5:$H$112,"M_PR",'108案详情'!$K$5:$K$112,"继承风险") -> 0 | D10: =COUNTIFS('108案详情'!$H$5:$H$112,"M_PR",'108案详情'!$K$5:$K$112,"重塑风险") -> 0 | E10: =COUNTIFS('108案详情'!$H$5:$H$112,"M_PR",'108案详情'!$K$5:$K$112,"稳定币特有风险") -> 3
A11: M_CR 信心挤兑 | B11: =SUM(C11:E11) -> 2 | C11: =COUNTIFS('108案详情'!$H$5:$H$112,"M_CR",'108案详情'!$K$5:$K$112,"继承风险") -> 1 | D11: =COUNTIFS('108案详情'!$H$5:$H$112,"M_CR",'108案详情'!$K$5:$K$112,"重塑风险") -> 1 | E11: =COUNTIFS('108案详情'!$H$5:$H$112,"M_CR",'108案详情'!$K$5:$K$112,"稳定币特有风险") -> 0
A12: E_IN 外部集成 | B12: =SUM(C12:E12) -> 25 | C12: =COUNTIFS('108案详情'!$H$5:$H$112,"E_IN",'108案详情'!$K$5:$K$112,"继承风险") -> 18 | D12: =COUNTIFS('108案详情'!$H$5:$H$112,"E_IN",'108案详情'!$K$5:$K$112,"重塑风险") -> 7 | E12: =COUNTIFS('108案详情'!$H$5:$H$112,"E_IN",'108案详情'!$K$5:$K$112,"稳定币特有风险") -> 0
A13: E_IU 违法利用 | B13: =SUM(C13:E13) -> 15 | C13: =COUNTIFS('108案详情'!$H$5:$H$112,"E_IU",'108案详情'!$K$5:$K$112,"继承风险") -> 3 | D13: =COUNTIFS('108案详情'!$H$5:$H$112,"E_IU",'108案详情'!$K$5:$K$112,"重塑风险") -> 12 | E13: =COUNTIFS('108案详情'!$H$5:$H$112,"E_IU",'108案详情'!$K$5:$K$112,"稳定币特有风险") -> 0
A14: E_RJ 监管法域 | B14: =SUM(C14:E14) -> 7 | C14: =COUNTIFS('108案详情'!$H$5:$H$112,"E_RJ",'108案详情'!$K$5:$K$112,"继承风险") -> 0 | D14: =COUNTIFS('108案详情'!$H$5:$H$112,"E_RJ",'108案详情'!$K$5:$K$112,"重塑风险") -> 1 | E14: =COUNTIFS('108案详情'!$H$5:$H$112,"E_RJ",'108案详情'!$K$5:$K$112,"稳定币特有风险") -> 6
A15: 合计 | B15: =SUM(B5:B14) -> 108 | C15: =SUM(C5:C14) -> 31 | D15: =SUM(D5:D14) -> 53 | E15: =SUM(E5:E14) -> 24
A18: 分析空间
A19: 分析空间 | B19: 数量 | C19: 占全部事件
A20: 核心机制 | B20: =COUNTIF('108案详情'!$I$5:$I$112,A20) -> 51 | C20: =B20/$B$15 -> 0.47222222
A21: 市场运行 | B21: =COUNTIF('108案详情'!$I$5:$I$112,A21) -> 10 | C21: =B21/$B$15 -> 0.092592593
A22: 外部生态 | B22: =COUNTIF('108案详情'!$I$5:$I$112,A22) -> 47 | C22: =B22/$B$15 -> 0.43518519
A23: 合计 | B23: =SUM(B20:B22) -> 108 | C23: =SUM(C20:C22) -> 1
A26: 市场表现与传播
A27: 统计项目 | B27: 数量 | C27: 占全部事件
A28: 记录为脱锚 | B28: =COUNTIF('108案详情'!$N$5:$N$112,"是") -> 32 | C28: =B28/$B$15 -> 0.2962963
A29: 局部/短时价格偏离 | B29: =COUNTIF('108案详情'!$N$5:$N$112,"局部/短时") -> 12 | C29: =B29/$B$15 -> 0.11111111
A30: 至少一次跨空间传播 | B30: =$B$15-COUNTIF('108案详情'!$R$5:$R$112,"C")-COUNTIF('108案详情'!$R$5:$R$112,"M")-COUNTIF('108案详情'!$R$5:$R$112,"E") -> 45 | C30: =B30/$B$15 -> 0.41666667
A33: 分类说明
A34: 风险起点依据最先出现的关键风险条件；后续价格下跌、挤兑或损失不自动改变起点。
A35: 继承：去掉稳定价值目标后，风险在一般区块链或加密资产系统中仍然成立。
A36: 重塑：稳定价值目标或机制改变既有风险的触发条件、传播方式或影响范围。
A37: 特有：直接来自维持稳定价值所增加的资产支撑、兑付承诺、铸赎或稳定机制。
A38: 事件时间保留来源精度；区间、公告与披露时间按原记录展示。
A39: 资产证明用于识别资产；来源未明确事件链版本时，证明链接不代表事件发生链。

Sheet 108案详情
A2: 108起稳定币安全事件 | B2: 108起稳定币安全事件（v3.1勘误版） | C2: 108起稳定币安全事件（v3.1勘误版） | D2: 108起稳定币安全事件（v3.1勘误版）
A4: 序号 | B4: 事件时间 | C4: 事件名称 | D4: 稳定币/资产版本 | E4: 链/主要场景 | F4: 价值支撑方式 | G4: 稳定币角色 | H4: 风险起点 | I4: 风险空间 | J4: 风险类型 | K4: 风险性质 | L4: 首个关键风险条件 | M4: 事件过程 | N4: 价格偏离情况 | O4: 市场表现 | P4: 影响规模 | Q4: 处置结果 | R4: 传播空间序列 | S4: 证据限定 | T4: 事件依据 | U4: 资产证明
A5: 1 | B5: 2016-06-01—2019-02-25被调查陈述；2021-10-15命令 | C5: Tether：CFTC储备陈述执法和解 | D5: USDT | E5: Tether储备／银行体系 | F5: 法币储备型稳定币或其外部使用/处置场景 | G5: USDT是CFTC审查其储备支持陈述的稳定币 | H5: C_VS | I5: 核心机制 | J5: 核心机制—价值支撑风险 | K5: 稳定币特有风险 | L5: Tether在调查期内并非所有时点都以足额法币储备支持USDT，却作出充分储备相关陈述 | M5: 储备支持陈述与实际覆盖不一致 → 监管调查 → CFTC罚款4100万美元 → 储备披露治理加强 | N5: 否 | O5: USDT未以调查期脱锚作为核心结果；监管关注点是储备覆盖与对外陈述。 | P5: CFTC罚款4,100万美元；调查样本中仅27.6%的天数拥有足额法币储备 | Q5: Tether与CFTC和解并支付4,100万美元民事罚款，储备披露和构成随后加强 | R5: C→E | T5: 事件依据 | U5: 资产证明
A6: 2 | B6: 2017—2019相关行为；2021-02-23和解 | C6: Bitfinex／Tether：NYAG储备调查和解 | D6: USDT | E6: Bitfinex／Tether关联资金体系 | F6: 法币储备型稳定币或其外部使用/处置场景 | G6: USDT是储备与Bitfinex关联资金缺口相互耦合的稳定币 | H6: C_VS | I6: 核心机制 | J6: 核心机制—价值支撑风险 | K6: 稳定币特有风险 | L6: Bitfinex约8.5亿美元资金缺口通过Tether储备/关联交易安排获得流动性支持 | M6: Bitfinex资金缺口 → 动用/借用Tether相关储备流动性 → USDT储备独立性受质疑 → NYAG和解 | N6: 否 | O6: USDT未发生由该调查直接确认的持续脱锚；核心是储备独立性和关联方流动性风险。 | P6: Bitfinex约8.5亿美元资金缺口；与Tether达成1,850万美元和解并接受限制措施 | Q6: Bitfinex/Tether与纽约州总检察长达成1,850万美元和解并接受储备/交易限制及报告义务 | R6: C→E | T6: 事件依据 | U6: 资产证明
A7: 3 | B7: 2018-11-25；2019-02-15报道回顾 | C7: BitShares bitUSD：全局清算后借币停止 | D7: bitUSD；BTS为抵押资产 | E7: BitShares | F7: 加密资产超额抵押；BTS抵押支持bitUSD | G7: bitUSD是全局清算后停止新增借币并长期脱锚的稳定币 | H7: C_VS | I7: 核心机制 | J7: 核心机制—价值支撑风险 | K7: 稳定币特有风险 | L7: BTS持续下跌使抵押不足恶化，系统触发Global Settlement并停止常规新增借币 | M7: BTS抵押价值下降 → 系统抵押率恶化 → Global Settlement → 停止新增借币 → bitUSD长期脱锚 | N7: 是 | O7: 发生明显或持续性脱锚/折价，价格稳定性受到实质破坏；触发Global Settlement后长期停止新增借币并低于1美元 | P7: 触发Global Settlement后长期停止新增借币并低于1美元 | Q7: bitUSD进入全局清算并长期受限，后续社区通过机制提案讨论恢复和防止再次触发 | R7: C→M | T7: 事件依据 | U7: 资产证明
A8: 4 | B8: 2020-11—2023-04被指行为；2024-09-24公告 | C8: TrueCoin／TrustToken：TUSD储备披露与SEC和解 | D8: TUSD | E8: TUSD储备与离岸基金 | F8: 法币/RWA储备型TUSD；储备曾配置离岸投资基金 | G8: TUSD是储备披露与离岸基金投资安排的监管对象 | H8: C_VS | I8: 核心机制 | J8: 核心机制—价值支撑风险 | K8: 稳定币特有风险 | L8: TUSD储备资金被大量配置到离岸投资基金，实际资产安排与对外储备陈述之间出现重大差异 | M8: 储备投向离岸基金 → 资产透明度/合规性下降 → 监管调查 → SEC和解并要求整改 | N8: 否 | O8: TUSD未以事件期市场脱锚作为主要监管事实；核心是储备质量、流动性和披露真实性。 | P8: 超过5亿美元TUSD储备被投入离岸基金；SEC称到2024年约99%储备位于该基金 | Q8: TrueCoin/TrustToken与SEC达成和解并接受处罚/整改，TUSD储备透明度成为监管重点 | R8: C→E | T8: 事件依据 | U8: 资产证明
A9: 5 | B9: 2022-04—2022-12（多次脱锚） | C9: Neutrino Protocol | D9: USDN | E9: Waves | F9: 加密资产支持／算法型；WAVES-USDN铸赎与再资本化 | G9: USDN是直接脱锚对象，WAVES价值与资本化能力构成其核心支撑 | H9: C_VS | I9: 核心机制 | J9: 核心机制—价值支撑风险 | K9: 稳定币特有风险 | L9: WAVES价格下跌、抵押关联度高及再资本化能力不足，使USDN价值支撑持续承压 | M9: WAVES支撑能力下降 → USDN抵押不足/信心恶化 → 持续脱锚 → 再资本化与机制调整 → XTN转型 | N9: 是 | O9: 发生明显或持续性脱锚/折价，价格稳定性受到实质破坏；2022年4月USDN一度约0.78美元，年内反复脱锚，最终停止维持1美元目标并转为XTN | P9: 2022年4月USDN一度约0.78美元，年内反复脱锚，最终停止维持1美元目标并转为XTN | Q9: USDN经过多轮参数调整仍未恢复稳定，最终更名XTN并放弃固定1美元目标 | R9: C→M | T9: 事件依据 | U9: 资产证明
A10: 6 | B10: 2022-10-24 | C10: NEAR USN：停止铸造与受控退出 | D10: USN | E10: NEAR／Decentral Bank | F10: 混合机制USN；由算法模式转向更强抵押支持 | G10: USN是出现约4000万美元抵押缺口后停止铸造并受控退出的稳定币 | H10: C_VS | I10: 核心机制 | J10: 核心机制—价值支撑风险 | K10: 稳定币特有风险 | L10: 历史机制与资产负债表累积约4000万美元抵押缺口，继续铸造将扩大未覆盖负债 | M10: 发现约4000万美元抵押缺口 → 停止新铸USN → NEAR保护计划接管缺口 → 受控清算退出 | N10: 否 | O10: USN在发现约4,000万美元抵押缺口后停止新铸造并由NEAR保护计划承接，未以无序市场脱锚作为主要处置路径。 | P10: 约4,000万美元抵押缺口，由NEAR保护计划承担并推动退出 | Q10: Decentral Bank停止USN新铸造，NEAR保护计划承担缺口并推进持有人受控退出 | R10: C | T10: 事件依据 | U10: 资产证明
A11: 7 | B11: 2022-12—2023-02；后续机制说明至2023-07 | C11: USDN：年末失稳处置与XTN转型 | D11: Waves原生USDN，后更名XTN；ERC20映射另论 | E11: Waves主网 | F11: 加密资产支持／算法型；WAVES-USDN铸赎与再资本化 | G11: USDN是持续脱锚并最终转型为XTN的稳定币 | H11: C_VS | I11: 核心机制 | J11: 核心机制—价值支撑风险 | K11: 稳定币特有风险 | L11: WAVES/生态信用持续恶化与抵押结构弱化，使USDN多次脱锚后难以恢复 | M11: 支撑资产/生态信心走弱 → 多轮抛售与赎回 → USDN持续脱锚 → 机制调整与债务处置 → XTN转型 | N11: 是 | O11: 发生明显或持续性脱锚/折价，价格稳定性受到实质破坏；2022年4月最低约0.78美元，后续长期低于锚定并转型XTN | P11: 2022年4月最低约0.78美元，后续长期低于锚定并转型XTN | Q11: USDN最终转型XTN并放弃固定美元锚定，Waves生态转向新的风险处置机制 | R11: C→M | T11: 事件依据 | U11: 资产证明
A12: 8 | B12: 2023-03-10—2023-03-15 | C12: SVB 冲击 USDC | D12: USDC／USD Coin | E12: 储备银行／多链；研究覆盖Ethereum、Avalanche、Solana、TRON | F12: 法币储备型；USDC以现金及高流动性美元资产支持 | G12: USDC是链下储备银行风险直接传导至链上价格与赎回预期的稳定币 | H12: C_VS | I12: 核心机制 | J12: 核心机制—价值支撑风险 | K12: 稳定币特有风险 | L12: SVB关闭导致Circle有33亿美元储备暂时面临银行可用性风险，市场先行重估兑付预期 | M12: SVB关闭 → USDC部分储备短时不可用 → 赎回担忧与抛售 → USDC脱锚 → 政策保障/银行可用性恢复 → 回锚 | N12: 是 | O12: 发生明显或持续性脱锚/折价，价格稳定性受到实质破坏；Circle披露33亿美元USDC储备位于SVB；USDC一度跌至约0.87—0.88美元 | P12: Circle披露33亿美元USDC储备位于SVB；USDC一度跌至约0.87—0.88美元 | Q12: 美国监管处置SVB存款风险后Circle恢复赎回，USDC在数日内回到1美元附近 | R12: C→M | T12: 事件依据 | U12: 资产证明
A13: 9 | B13: 2023-10-11失稳；处置材料至2025-09-16 | C13: USDR：房地产储备与即时兑付缺口 | D13: Tangible Real USD（USDR）；非其他同符号代币 | E13: Polygon；2024赎回安排迁至re.al，2025拟返回Polygon | F13: RWA储备型；房地产+DAI等流动储备 | G13: USDR是房地产储备与有限流动储备共同支持、发生兑付危机的稳定币 | H13: C_VS | I13: 核心机制 | J13: 核心机制—价值支撑风险 | K13: 稳定币特有风险 | L13: 大部分储备为房地产等非即时流动资产，而可立即赎回的DAI储备规模有限 | M13: 市场赎回加速 → 约1180万DAI流动储备耗尽 → 房地产难即时变现 → 兑付预期崩塌 → USDR暴跌 | N13: 是 | O13: 发生明显或持续性脱锚/折价，价格稳定性受到实质破坏；约1,180万DAI流动储备被迅速耗尽，USDR价格大幅崩跌 | P13: 约1,180万DAI流动储备被迅速耗尽，USDR价格大幅崩跌 | Q13: Tangible停止正常USDR机制并推进赎回/资产处置，持有人通过后续安排回收价值 | R13: C→M | T13: 事件依据 | U13: 资产证明
A14: 10 | B14: 2025-04-16退出提案；2025-07-02完成 | C14: Inter Protocol／IST：分阶段停止运行 | D14: IST | E14: Agoric／Inter Protocol | F14: 多抵押+PSM稳定币IST；链上治理管理Vault与兑付模块 | G14: IST是治理决定分阶段停止Vault/PSM并退出的稳定币 | H14: C_VS | I14: 核心机制 | J14: 核心机制—价值支撑风险 | K14: 稳定币特有风险 | L14: 治理决定停止IST生态，Vault/PSM和债务头寸按计划分阶段关闭 | M14: 治理通过退出 → Vault/PSM停止扩张 → 用户偿还/赎回 → IST负债与供应逐步收缩 | N14: 否 | O14: IST按治理计划退出，没有以安全攻击或无序脱锚为主要结果；供应随债务关闭收缩。 | P14: 无攻击损失；IST的Vault/PSM和债务体系按治理计划退出 | Q14: Inter Protocol按治理方案完成/推进Vault、PSM与债务退出，IST供应逐步收缩 | R14: C | S14: 治理退出方向明确；具体全部完成节点以社区治理资料为主 | T14: 事件依据 | U14: 资产证明
A15: 11 | B15: 2025-05-12起；2025-08-22进入第三阶段 | C15: Mountain USDM：退出转向Uniswap与USDC储备 | D15: USDM（退出期转为USDC储备/AMM退出） | E15: Ethereum／Uniswap V4退出池 | F15: 收益型法币/RWA储备USDM；退出后转为USDC+AMM流动性 | G15: USDM是发行方主动退出并改变赎回/储备结构的稳定币 | H15: C_VS | I15: 核心机制 | J15: 核心机制—价值支撑风险 | K15: 稳定币特有风险 | L15: 发行人主动wind-down，直接美元赎回逐步转为USDC储备和Uniswap流动性退出 | M15: 主动停止发行 → 赎回模式切换 → USDC储备/Uniswap承接退出 → USDM供应逐步收缩 | N15: 否 | O15: USDM按wind-down计划退出，未以无序脱锚收尾；主要表现为供应收缩和赎回路径迁移。 | P15: 无攻击损失；USDM发行退出并将剩余退出流动性迁移至USDC/Uniswap | Q15: Mountain按wind-down计划停止常规发行，将退出路径转为USDC储备和Uniswap市场 | R15: C | T15: 事件依据 | U15: 资产证明
A16: 12 | B16: 2025-10-08公告；2025-12-08计划转换 | C16: Paxos USDL：停止发行与迁移USDG安排 | D16: USDL；迁移目标USDG | E16: Ethereum／Paxos发行体系 | F16: 法币/T-bill储备收益型USDL；发行人主导赎回与迁移 | G16: USDL是停止发行、收益和直接美元赎回并迁移至USDG的稳定币 | H16: C_VS | I16: 核心机制 | J16: 核心机制—价值支撑风险 | K16: 稳定币特有风险 | L16: Paxos决定停止USDL发行、收益与直接美元赎回，并安排符合条件余额迁移为USDG | M16: 停止USDL发行与收益 → 直接美元赎回终止 → 小额/合格余额转换USDG → 产品退出 | N16: 否 | O16: USDL有序退出，未以市场脱锚为主要事件结果；供应和收益功能按计划终止。 | P16: 无攻击损失；USDL停止铸造、收益和直接美元赎回并安排USDG转换 | Q16: Paxos按计划wind-down USDL并引导合格持有人迁移USDG，产品进入关闭阶段 | R16: C | T16: 事件依据 | U16: 资产证明
A17: 13 | B17: 2025-11-04（损失披露日） | C17: Stream xUSD：外部资产管理损失与退出暂停 | D17: Stream Finance xUSD | E17: 外部基金管理＋Euler／Morpho／Silo等DeFi依赖 | F17: 收益型合成美元；资产由外部基金经理及DeFi借贷策略管理 | G17: xUSD是外部资产管理亏损后暂停赎回并严重折价的稳定币 | H17: C_VS | I17: 核心机制 | J17: 核心机制—价值支撑风险 | K17: 稳定币特有风险 | L17: 外部基金管理人披露约9300万美元资产损失，Stream暂停存取款并暴露复杂DeFi敞口 | M17: 链下资产管理损失 → Stream暂停存取款 → xUSD兑付信心崩溃 → DeFi借贷敞口传染 → xUSD严重折价 | N17: 是 | O17: 发生明显或持续性脱锚/折价，价格稳定性受到实质破坏；Stream披露外部基金管理人损失约9,300万美元；xUSD最低约0.26美元，DeFi潜在敞口约2.85亿美元 | P17: Stream披露外部基金管理人损失约9,300万美元；xUSD最低约0.26美元，DeFi潜在敞口约2.85亿美元 | Q17: Stream暂停提款并进入调查/重组，xUSD严重失稳且外部DeFi协议被迫处置敞口 | R17: C→M→E→M | S17: Stream公开约9300万美元外部管理损失；具体损失形成时间和资产构成披露有限 | T17: 事件依据 | U17: 资产证明
A18: 14 | B18: 2026-05-15公告；初始赎回期至2026-11-11 | C18: GMO Trust：GYEN与ZUSD共同退出发行 | D18: GYEN、ZUSD | E18: Ethereum／GMO Trust发行体系 | F18: 法币储备型；GYEN锚定JPY、ZUSD锚定USD | G18: GYEN和ZUSD是发行人主动进入有序退出和赎回期的稳定币 | H18: C_VS | I18: 核心机制 | J18: 核心机制—价值支撑风险 | K18: 稳定币特有风险 | L18: GMO Trust主动停止GYEN/ZUSD新发行并设定统一赎回窗口 | M18: 停止GYEN/ZUSD新发行 → 进入赎回窗口 → 供应逐步收缩 → 产品有序退出 | N18: 否 | O18: GYEN/ZUSD有序退出，未以系统性脱锚为主要事件结果；核心是发行和赎回生命周期结束。 | P18: 无攻击损失；GYEN/ZUSD进入约180天初始赎回期 | Q18: GMO Trust停止GYEN/ZUSD新发行并维持赎回窗口，产品进入有序退出 | R18: C | T18: 事件依据 | U18: 资产证明
A19: 15 | B19: 2021-01-07 | C19: PolBase Cash特权提现／疑似Rug Pull | D19: PBC | E19: Ethereum | F19: 算法型；PBC/PBB/PBS三Token seigniorage结构 | G19: PBC是项目算法稳定币；资金损失来自管理员提取质押资产 | H19: C_PR | I19: 核心机制 | J19: 链上协议—协议规则缺陷 | K19: 继承风险 | L19: 部署者可通过setOperation等特权入口变更资金控制者并提取staking资产 | M19: 管理员设置资金操作地址 → staking资产被提取并撤流动性 → PBC生态信心与流动性受损 | N19: 否 | O19: 未观察到PBC系统性价格数据可可靠量化；主要表现为质押资产被特权地址提取和项目流动性损失。 | P19: 约353,807美元质押/流动性资产被提取 | Q19: 项目流动性/质押资产被提走后失去正常运营能力，按疑似Rug Pull记录 | R19: C→M | S19: 链上权限与资金转移可核，但缺少项目官方技术复盘 | T19: 事件依据 | U19: 资产证明
A20: 16 | B20: 2021-03-15 | C20: True Seigniorage Dollar | D20: TSD | E20: BSC | F20: 无抵押算法型；seigniorage与DAO治理 | G20: TSD是治理被接管后被巨量异常铸造的算法稳定币 | H20: C_PR | I20: 核心机制 | J20: 链上协议—协议规则缺陷 | K20: 继承风险 | L20: TSD价格低迷和治理参与下降使攻击者能低成本积累足够治理权并升级恶意实现 | M20: 治理参与枯竭 → 攻击者买入并控制提案 → 恶意升级 → 巨量TSD铸造 → 薄流动性市场被抽取 | N20: 是 | O20: 发生明显或持续性脱锚/折价，价格稳定性受到实质破坏；异常铸造约118亿TSD，但薄流动性下实际套现约1.66万美元 | P20: 异常铸造约118亿TSD，但薄流动性下实际套现约1.66万美元 | Q20: TSD供应和市场功能遭破坏，项目未形成有效恢复 | R20: C→M | S20: 治理攻击机制明确；约118亿TSD是异常铸造量，不等于同额美元损失 | T20: 事件依据 | U20: 资产证明
A21: 17 | B21: 2021-08-04（执行约01:43:52—01:49:05 UTC） | C21: Wault／WUSD：固定兑价与储备换币反馈 | D21: WUSD；USDT为主要储备，WEX为内生资产 | E21: BSC | F21: 混合储备；约90% USDT+10% WEX支持WUSD | G21: WUSD是固定USDT兑价和WEX储备反馈被反向利用的稳定币 | H21: C_PR | I21: 核心机制 | J21: 链上协议—协议规则缺陷 | K21: 重塑风险 | L21: WUSD按固定1:1 USDT铸赎，而相关操作同时影响WEX市场价格，形成可循环套利反馈 | M21: 固定USDT兑价铸赎 → WEX市场价格被操作影响储备 → 循环套利 → WUSD储备/锚定承压 | N21: 是 | O21: 发生明显或持续性脱锚/折价，价格稳定性受到实质破坏；约80万美元直接损失，WUSD稳定机制与储备承受冲击 | P21: 约80万美元直接损失，WUSD稳定机制与储备承受冲击 | Q21: Wault修复WUSD储备/兑换机制并处置损失，事件暴露固定兑价与内生Token反馈问题 | R21: C→M | T21: 事件依据 | U21: 资产证明
A22: 18 | B22: 2021-11-11 | C22: Mochi Finance | D22: USDM | E22: Ethereum | F22: 抵押借贷型；MOCHI等抵押生成USDM | G22: USDM是由项目方高权限抵押/发行安排扩张并进入外部池的稳定币 | H22: C_PR | I22: 核心机制 | J22: 链上协议—协议规则缺陷 | K22: 重塑风险 | L22: 项目方可大量铸MOCHI并影响其价格，同时以高LTV借出USDM，发行约束高度集中 | M22: 特权铸造MOCHI/控制估值 → 大量借出USDM → 换走DAI并购买CVX → Curve撤销激励 → USDM池失衡与折价 | N22: 是 | O22: 发生明显或持续性脱锚/折价，价格稳定性受到实质破坏；约4,600万USDM被生成/借出并换取DAI；相关Curve池流动性峰值曾超过1.7亿美元 | P22: 约4,600万USDM被生成/借出并换取DAI；相关Curve池流动性峰值曾超过1.7亿美元 | Q22: Curve Emergency DAO撤销USDM gauge激励，USDM市场流动性与可信度显著下降 | R22: C→M | S22: Curve治理记录与链上行为支持核心过程；更适合归为高度集中权限/经济治理风险 | T22: 事件依据 | U22: 资产证明
A23: 19 | B23: 2022-04-13 | C23: Elephant Money | D23: TRUNK | E23: BSC | F23: 储备／双Token机制；TRUNK与ELEPHANT生态联动 | G23: TRUNK是Reserve与ELEPHANT回购/铸赎反馈中的稳定资产 | H23: C_PR | I23: 核心机制 | J23: 链上协议—协议规则缺陷 | K23: 重塑风险 | L23: TRUNK mint/redeem、Reserve与ELEPHANT回购之间缺少严格资产会计不变量 | M23: 闪电贷改变ELEPHANT/TRUNK状态 → mint/redeem与回购反馈失真 → Reserve被抽取 → TRUNK支撑能力受损 | N23: 局部/短时 | O23: TRUNK相关市场在攻击后承压并出现短时价格扰动；核心损失是Reserve约1,120万美元被抽取，而非长期死亡螺旋。 | P23: 官方确认损失27,416 BNB，按当时价格约1,120万美元 | Q23: Elephant暂停Reserve与TRUNK铸赎并调整机制；协议储备受到实质损失 | R23: C→M | T23: 事件依据 | U23: 资产证明
A24: 20 | B24: 2022/4/17 | C24: Beanstalk 治理攻击 | D24: Bean／BEAN（事件时版本） | E24: Ethereum | F24: 信用／算法型；Beanstalk治理与内生信用机制 | G24: BEAN是协议负债与治理攻击后的价值受损对象 | H24: C_PR | I24: 核心机制 | J24: 链上协议—协议规则缺陷 | K24: 继承风险 | L24: 治理投票权可被闪电贷瞬时集中，攻击者利用紧急治理提案转移协议资产 | M24: 治理权瞬时集中 → 恶意提案通过 → 协议资产被转走 → BEAN信用受损与市场折价 | N24: 是 | O24: 发生明显或持续性脱锚/折价，价格稳定性受到实质破坏；约7,700万美元非BEAN资产被盗；协议估计总经济损失约1.82亿美元 | P24: 约7,700万美元非BEAN资产被盗；协议估计总经济损失约1.82亿美元 | Q24: Beanstalk通过融资/重启恢复协议运行，并重构治理安全机制 | R24: C→M | T24: 事件依据 | U24: 资产证明
A25: 21 | B25: 2023-09-21 | C25: Linear Finance发行权限失陷 | D25: lUSD（小写） | E25: BSC | F25: 合成资产债务池；ℓUSD由Linear合成资产体系支持 | G25: ℓUSD是攻击者用无限铸造的ℓAAVE在系统内兑换并对外抛售的稳定币 | H25: C_PR | I25: 核心机制 | J25: 链上协议—协议规则缺陷 | K25: 重塑风险 | L25: 高权限角色被异常授予ISSUE_ASSET权限，攻击合约获得合法无限发行ℓAAVE能力 | M25: ISSUE_ASSET权限失陷 → 无限铸ℓAAVE → 内部换成ℓUSD → 外部市场抛售 → ℓUSD流动性被抽干 | N25: 是 | O25: 发生明显或持续性脱锚/折价，价格稳定性受到实质破坏；约21.2万美元级攻击收益；ℓUSD主要流动性被快速抽干 | P25: 约21.2万美元级攻击收益；ℓUSD主要流动性被快速抽干 | Q25: Linear暂停mint/burn/exchange及桥接并追踪攻击地址，ℓUSD流动性随后重建有限 | R25: C→M | T25: 事件依据 | U25: 资产证明
A26: 22 | B26: 2026/3/22 | C26: Resolv／USR 异常铸造（扩充候选） | D26: USR（非USDe） | E26: Ethereum | F26: 市场中性储备型；USR依赖抵押资产与链下授权铸币 | G26: USR是发行权限失陷后被大量无储备异常铸造的稳定币 | H26: C_PR | I26: 核心机制 | J26: 链上协议—协议规则缺陷 | K26: 重塑风险 | L26: 链下授权/签名发行权限被攻陷，攻击者可绕过正常抵押/入金流程铸造USR | M26: 发行权限被攻陷 → USR无抵押巨量铸造 → 抛售/流动性抽取 → USR价格崩溃 → 项目应急处置 | N26: 是 | O26: 发生明显或持续性脱锚/折价，价格稳定性受到实质破坏；攻击者异常铸造约8,000万USR，USR随后跌至几美分水平 | P26: 攻击者异常铸造约8,000万USR，USR随后跌至几美分水平 | Q26: Resolv暂停/调整发行权限和相关合约，USR生态遭受严重信用与市场损失 | R26: C→M | S26: 安全机构与项目通报支持约8000万USR异常铸造；发行权限具体攻陷入口以公开资料为准 | T26: 事件依据 | U26: 资产证明
A27: 23 | B27: 2026-05-23—05-25；2026-08-25更新 | C27: StablR USDR／EURR未经授权发行 | D27: StablR USDR、EURR（区别Tangible USDR） | E27: StablR发行基础设施／链上USDR与EURR | F27: 法币储备型；USDR/EURR依赖发行基础设施与隔离储备 | G27: USDR/EURR是发行基础设施被攻陷后产生无对应储备供应的稳定币 | H27: C_PR | I27: 核心机制 | J27: 链上协议—协议规则缺陷 | K27: 重塑风险 | L27: 发行基础设施被攻击，攻击者绕过“入金—储备—授权铸币”流程直接生成USDR/EURR | M27: 发行系统入侵 → 无入金USDR/EURR被铸造 → 总供应超过合法储备 → 铸赎/交易暂停 → 调查与处置 | N27: 否 | O27: 未以市场脱锚作为核心结果；首要问题是链上未经授权供应超过合法储备覆盖范围，铸赎被暂停。 | P27: 未经授权供应约1,433万USDR和641万EURR，均无对应客户入金和新增储备 | Q27: StablR暂停USDR/EURR铸赎及交易协作，调查未经授权供应并保护合法储备 | R27: C | S27: StablR官方披露未经授权供应规模；具体密钥/多签攻陷路径未完全公开 | T27: 事件依据 | U27: 资产证明
A28: 24 | B28: 2020-11-17 | C28: Origin Protocol | D28: OUSD | E28: Ethereum | F28: 储备收益型；USDC/USDT/DAI等底层资产支持OUSD | G28: OUSD是铸币/重入会计漏洞直接异常生成的收益型稳定币 | H28: C_CI | I28: 核心机制 | J28: 链上协议—合约实现缺陷 | K28: 重塑风险 | L28: OUSD mint路径缺少完整资产校验和重入保护，外部Token回调可重复进入会计流程 | M28: 恶意Token回调重入 → OUSD铸币/rebase重复记账 → 异常OUSD赎回 → 储备被抽走 → OUSD折价 | N28: 是 | O28: 发生明显或持续性脱锚/折价，价格稳定性受到实质破坏；约700万—770万美元储备资产损失 | P28: 约700万—770万美元储备资产损失 | Q28: Origin暂停OUSD并补偿受影响用户，之后以更严格安全控制重启 | R28: C→M | T28: 事件依据 | U28: 资产证明
A29: 25 | B29: 2021-06-22—2021-06-29 | C29: Haven Protocol | D29: xUSD | E29: Haven | F29: 加密资产支持／隐私合成资产；XHV与xUSD/xAssets转换 | G29: xUSD是资产转换验证漏洞导致异常生成的核心稳定资产 | H29: C_CI | I29: 核心机制 | J29: 链上协议—合约实现缺陷 | K29: 重塑风险 | L29: mint/burn、价格记录与隐私资产转换验证存在多处边界条件和一致性漏洞 | M29: 转换验证漏洞 → xUSD/xBTC等异常生成 → 供应可信度受损 → 协议暂停 → 硬分叉回滚异常状态 | N29: 否 | O29: 未以持续脱锚作为主要结果；核心风险是xUSD/xAssets异常增发，协议最终通过硬分叉回滚主要异常状态。 | P29: 异常生成约900万xUSD及其他xAssets；协议通过硬分叉回滚主要异常状态 | Q29: Haven暂停转换并经社区硬分叉回滚，重写mint/burn验证后恢复网络 | R29: C | T29: 事件依据 | U29: 资产证明
A30: 26 | B30: 2021-06-28 | C30: SafeDollar | D30: SDO | E30: Polygon | F30: 算法型；SDO与奖励／通缩Token生态 | G30: SDO是奖励会计漏洞导致天量异常增发并抛售的稳定币 | H30: C_CI | I30: 核心机制 | J30: 链上协议—合约实现缺陷 | K30: 重塑风险 | L30: 奖励公式未正确处理带转账销毁的PLX，反复存取可把lpSupply分母压至极小 | M30: PLX转账销毁反复压低lpSupply → 单位奖励被极端放大 → SDO天量增发 → 抛售抽干USDC/USDT → 归零 | N30: 是 | O30: 发生明显或持续性脱锚/折价，价格稳定性受到实质破坏；约24.8万美元，包含约202,230 USDC与46,000 USDT | P30: 约24.8万美元，包含约202,230 USDC与46,000 USDT | Q30: SafeDollar暂停并尝试补偿/重构，但SDO价格归零后未恢复 | R30: C→M | T30: 事件依据 | U30: 资产证明
A31: 27 | B31: 2022/3/23 | C31: Cashio 伪造抵押物铸币 | D31: CASH | E31: Solana／Ethereum（报告资金去向） | F31: 加密资产抵押；Saber LP Token抵押铸造CASH | G31: CASH是被无有效抵押异常铸造并抛售的核心稳定币 | H31: C_CI | I31: 核心机制 | J31: 链上协议—合约实现缺陷 | K31: 重塑风险 | L31: 抵押账户身份验证不完整，攻击者可构造伪造抵押路径通过铸币校验 | M31: 抵押校验绕过 → CASH无抵押增发 → 兑换真实稳定币 → 流动性被抽干 → CASH接近归零 | N31: 是 | O31: 发生明显或持续性脱锚/折价，价格稳定性受到实质破坏；约5,200万美元资产损失，CASH价格几乎归零 | P31: 约5,200万美元资产损失，CASH价格几乎归零 | Q31: Cashio停止正常运行，CASH未恢复有效稳定币功能 | R31: C→M | T31: 事件依据 | U31: 资产证明
A32: 28 | B32: 2022-07-28 | C32: Nirvana Finance：ANA定价曲线操纵致NIRV失稳 | D32: NIRV | E32: Solana | F32: 储备型算法稳定币；NIRV依赖ANA与协议金库 | G32: NIRV是金库被抽空后失去支持并脱锚的稳定币 | H32: C_CI | I32: 核心机制 | J32: 链上协议—合约实现缺陷 | K32: 重塑风险 | L32: ANA大额买入未按价格曲线正确提高边际价格，攻击者可低价买入后高价卖回金库 | M32: ANA定价曲线被绕过 → 低价大额买入 → 新高价卖回协议 → 金库被抽干 → NIRV失去支持并脱锚 | N32: 是 | O32: 发生明显或持续性脱锚/折价，价格稳定性受到实质破坏；约350万—360万美元金库资产被抽取，NIRV失去有效支撑 | P32: 约350万—360万美元金库资产被抽取，NIRV失去有效支撑 | Q32: Nirvana金库被抽空后停止正常运营，NIRV未恢复稳定币功能 | R32: C→M | T32: 事件依据 | U32: 资产证明
A33: 29 | B33: 2022-08-14 | C33: Acala Network | D33: aUSD | E33: Polkadot | F33: 多抵押稳定币；Acala抵押资产支持aUSD | G33: aUSD是奖励配置错误导致异常增发的核心稳定币 | H33: C_CI | I33: 核心机制 | J33: 链上协议—合约实现缺陷 | K33: 重塑风险 | L33: 新iBTC/aUSD池奖励参数/遗留逻辑配置错误，使正常领取奖励路径异常生成aUSD | M33: 奖励参数错误 → LP操作异常铸aUSD → 供应暴增 → 市场恐慌脱锚 → 链上治理冻结并销毁异常供应 | N33: 是 | O33: 发生明显或持续性脱锚/折价，价格稳定性受到实质破坏；异常铸造约30.22亿aUSD；绝大多数被识别、冻结并通过治理销毁 | P33: 异常铸造约30.22亿aUSD；绝大多数被识别、冻结并通过治理销毁 | Q33: Acala通过治理冻结、追踪并销毁绝大多数异常aUSD，后续逐步恢复链上服务 | R33: C→M | T33: 事件依据 | U33: 资产证明
A34: 30 | B34: 2022-11-08 | C34: Abracadabra旧价借款／新价自清算 | D34: MIM | E34: Ethereum | F34: 加密资产超额抵押；Cauldron抵押借出MIM | G34: MIM是利用旧/新价格状态不一致完成借款与自清算套利的稳定币 | H34: C_CI | I34: 核心机制 | J34: 链上协议—合约实现缺陷 | K34: 重塑风险 | L34: 借款偿付检查可使用缓存旧价，而清算先刷新新价，导致同一交易采用两套估值 | M34: 旧价通过偿付检查 → 主动刷新新价 → 自己仓位变为可清算 → 自清算套利约11万MIM | N34: 局部/短时 | O34: 出现局部或短时价格偏离，未观察到同等程度的全市场持续失稳；攻击者获利约110,911 MIM | P34: 攻击者获利约110,911 MIM | Q34: Abracadabra确认旧Cauldron逻辑问题并隔离风险，攻击规模有限且MIM未持续失稳 | R34: C→M | T34: 事件依据 | U34: 资产证明
A35: 31 | B35: 2022-12-23—2022-12-24 | C35: Defrost Finance | D35: H2O | E35: Avalanche | F35: 加密资产抵押；Defrost Vault抵押生成H2O | G35: H2O是Defrost抵押借贷体系稳定币，受管理员权限事件波及 | H35: C_CI | I35: 核心机制 | J35: 链上协议—合约实现缺陷 | K35: 继承风险 | L35: V1管理员权限被使用以加入恶意抵押品/预言机；权限来源是否外部失窃存在归因争议 | M35: 管理员权限被使用 → 恶意抵押/预言机加入 → 资产被抽走 → H2O体系受损 → 返还资金与退款处置 | N35: 否 | O35: H2O未形成可与资金损失同规模对应的系统性脱锚证据；核心影响是Defrost资金被抽走与权限信任危机。 | P35: V1损失超过1,200万美元；V2另约17万美元，后续大部分V1资金返还 | Q35: Defrost宣布遭攻击并建立退款方案；大部分V1资金返还，但权限归因争议保留 | R35: C | S35: 资金流失和owner权限使用明确，但“外部私钥失窃还是内部Rug Pull”无最终公开定论 | T35: 事件依据 | U35: 资产证明
A36: 32 | B36: 2023-02-03—2023-02-04 | C36: SperaxUSD | D36: USDs | E36: Arbitrum | F36: 抵押／收益型rebase稳定币USDs | G36: USDs是rebase余额迁移错误导致异常余额产生的稳定币 | H36: C_CI | I36: 核心机制 | J36: 链上协议—合约实现缺陷 | K36: 重塑风险 | L36: rebase账户迁移在“先向未部署合约地址转币、后部署合约”边界场景错误解释credits | M36: 迁移credits误作余额 → 11枚USDs触发数十亿异常余额 → 分批卖出真实资产 → 协议暂停与修复 | N36: 局部/短时 | O36: 异常USDs被分批卖出造成短时市场压力，但实际变现约30.9万USDs，未形成与97.9亿账面异常余额同规模的持续脱锚。 | P36: 账面异常余额约97.9亿USDs；实际卖出约30.9万USDs | Q36: Sperax快速暂停合约、修复迁移逻辑并处理异常供应，USDs恢复运行 | R36: C→M | T36: 事件依据 | U36: 资产证明
A37: 33 | B37: 2023-02-16 | C37: Platypus Finance | D37: USP | E37: Avalanche | F37: 超额抵押稳定币；LP资产抵押借出USP | G37: USP是债务仍在但抵押可被抽离后形成不足额支持的稳定币 | H37: C_CI | I37: 核心机制 | J37: 链上协议—合约实现缺陷 | K37: 重塑风险 | L37: emergencyWithdraw在债务未清偿时允许抵押品被取回，提款后偿付能力未被正确验证 | M37: 紧急提款偿付检查缺口 → 借出USP后取回抵押 → 无抵押USP进入市场 → 真实稳定币被换走 → USP脱锚 | N37: 是 | O37: 发生明显或持续性脱锚/折价，价格稳定性受到实质破坏；三轮相关攻击合计约919万美元；首轮约850万美元 | P37: 三轮相关攻击合计约919万美元；首轮约850万美元 | Q37: Platypus暂停协议并开展资产回收、补偿和技术修复；USP未恢复原有规模 | R37: C→M | T37: 事件依据 | U37: 资产证明
A38: 34 | B38: 2023-02-21 | C38: Kujira USK Margin估值漏洞 | D38: USK | E38: Kujira | F38: 加密资产超额抵押；USK抵押债务体系 | G38: USK是Margin合约错误估值下被异常铸造并形成坏账的稳定币 | H38: C_CI | I38: 核心机制 | J38: 链上协议—合约实现缺陷 | K38: 重塑风险 | L38: USK Margin对买入资产价值/订单执行校验错误，可用新铸USK高价接攻击者自有ETH卖单 | M38: Margin错误估值 → 新铸USK高价买入攻击者ETH → USK坏账 → 团队用USDC托底稳定性 | N38: 否 | O38: USK整体锚定未出现持续性崩溃；团队以USDC补足约23.6万USK坏账以维持抵押状态。 | P38: 形成约23.6万USK坏账，约26万美元量级 | Q38: Kujira以USDC买入/补足风险资产并修复Margin，USK维持整体抵押状态 | R38: C | T38: 事件依据 | U38: 资产证明
A39: 35 | B39: 2023-05-06 | C39: DEUS Finance | D39: DEI | E39: BSC、Arbitrum | F39: 混合抵押稳定币；DEI依赖抵押与DeFi流动性 | G39: DEI是Token授权逻辑缺陷直接影响的稳定币资产 | H39: C_CI | I39: 核心机制 | J39: 链上协议—合约实现缺陷 | K39: 继承风险 | L39: DEI burnFrom读取allowance时颠倒owner/spender索引，破坏授权语义 | M39: allowance索引错误 → 授权关系被颠倒 → 用户DEI可被转走 → 多链损失与DEI大幅下跌 | N39: 是 | O39: 发生明显或持续性脱锚/折价，价格稳定性受到实质破坏；跨链损失约630万—650万美元 | P39: 跨链损失约630万—650万美元 | Q39: DEUS暂停DEI合约并协调白帽/攻击资金返还；项目后续逐步退出DEI | R39: C→M | T39: 事件依据 | U39: 资产证明
A40: 36 | B40: 2023-07-24 | C40: Palmswap | D40: USDP | E40: BSC | F40: DEX内部稳定资产；Vault资产支持USDP/PLP体系 | G40: USDP是Palmswap内部结算资产；核心漏洞发生在PLP/Vault份额定价 | H40: C_CI | I40: 核心机制 | J40: 链上协议—合约实现缺陷 | K40: 重塑风险 | L40: Vault资产余额可在不同比例铸造PLP的情况下被直接增加，导致PLP单位价值被人为抬高 | M40: Vault资产增加但PLP供应不增 → PLP单价虚高 → 高价赎回 → 约90万USDT被抽走 | N40: 否 | O40: 未观察到有证据支持的系统性脱锚；主要影响体现为供应、储备、资金损失、兑付或服务可用性变化。 | P40: 攻击者获利约901,455 USDT，后返还约80% | Q40: 攻击者返还约80%资金，Palmswap修复Vault/manager限制并恢复部分服务 | R40: C | T40: 事件依据 | U40: 资产证明
A41: 37 | B41: 2023-11-10 | C41: Raft Finance | D41: R | E41: Ethereum | F41: 加密资产超额抵押；LST抵押借出R | G41: R是虚假抵押份额支持下被异常借出的稳定币 | H41: C_CI | I41: 核心机制 | J41: 链上协议—合约实现缺陷 | K41: 重塑风险 | L41: 捐赠可操纵collateralIndex，极小额存款又因向上舍入产生不应存在的抵押份额 | M41: 捐赠抬高collateralIndex → 向上舍入制造虚假share → 抵押能力虚增 → R被异常借出 → R脱锚 | N41: 是 | O41: 发生明显或持续性脱锚/折价，价格稳定性受到实质破坏；约670万R被异常借出；攻击者后续误将约1,570 ETH发送至不可恢复地址 | P41: 约670万R被异常借出；攻击者后续误将约1,570 ETH发送至不可恢复地址 | Q41: Raft暂停R铸造并制定恢复/赎回方案，R未恢复原有稳定币生态规模 | R41: C→M | T41: 事件依据 | U41: 资产证明
A42: 38 | B42: 2024-01-30 | C42: Abracadabra Money | D42: MIM | E42: Ethereum | F42: 加密资产超额抵押；Cauldron抵押借出MIM | G42: MIM是债务份额会计错误导致无充分抵押借出的稳定币 | H42: C_CI | I42: 核心机制 | J42: 链上协议—合约实现缺陷 | K42: 重塑风险 | L42: 债务elastic/base在特定还款路径后失配，舍入误差可被重复放大 | M42: 债务base/elastic失配 → 舍入偏差反复放大 → 债务被低估 → 约650万MIM异常借出 → MIM短时脱锚 | N42: 是 | O42: 发生明显或持续性脱锚/折价，价格稳定性受到实质破坏；约649万—650万美元MIM被异常借出 | P42: 约649万—650万美元MIM被异常借出 | Q42: Abracadabra隔离受影响Cauldron、修复债务会计并推进资金追踪；MIM随后回锚 | R42: C→M | T42: 事件依据 | U42: 资产证明
...

Sheet 来源
A2: 案件来源与资产证明 | B2: 案件来源与资产证明
A4: 序号 | B4: 事件/稳定币 | C4: 事件依据 | D4: 资产证明 | E4: 补充来源 | F4: 资产证明说明
A5: 1 | B5: Tether储备披露处罚/USDT | C5: 事件依据 | D5: 资产证明 | F5: 独立资产/官方证明
A6: 2 | B6: Tether储备调查和解/USDT | C6: 事件依据 | D6: 资产证明 | F6: 独立资产/官方证明
A7: 3 | B7: BitShares全局清算/bitUSD | C7: 事件依据 | D7: 资产证明 | F7: 事件来源兼资产证明
A8: 4 | B8: TrueCoin储备披露争议/TUSD | C8: 事件依据 | D8: 资产证明 | F8: 独立官方资产/产品证明
A9: 5 | B9: Neutrino多次脱锚/USDN | C9: 事件依据 | D9: 资产证明 | F9: 事件来源兼资产证明
A10: 6 | B10: NEAR资产缺口退出/USN | C10: 事件依据 | D10: 资产证明 | F10: 事件来源兼资产证明
A11: 7 | B11: Neutrino失稳转型/USDN | C11: 事件依据 | D11: 资产证明 | F11: 事件来源兼资产证明
A12: 8 | B12: Circle储备银行危机/USDC | C12: 事件依据 | D12: 资产证明 | F12: 独立资产/官方证明
A13: 9 | B13: Tangible兑付缺口/USDR | C13: 事件依据 | D13: 资产证明 | F13: 独立官方资产/产品证明
A14: 10 | B14: Inter Protocol停止运行/IST | C14: 事件依据 | D14: 资产证明 | F14: 独立资产/官方证明
A15: 11 | B15: Mountain有序退出/USDM | C15: 事件依据 | D15: 资产证明 | F15: 独立资产/官方证明
A16: 12 | B16: Paxos停止发行迁移/USDL | C16: 事件依据 | D16: 资产证明 | F16: 独立资产/官方证明
... A22: 18 | B22: Mochi特权信用扩张/USDM | C22: 事件依据 | D22: 资产证明 | F22: 事件来源兼资产证明
A23: 19 | B23: Elephant储备攻击/TRUNK | C23: 事件依据 | D23: 资产证明 | E23: https://crypto.training/hacks/2022-04-elephant_money/ | F23: 第二来源兼资产证明
A24: 20 | B24: Beanstalk闪贷治理/BEAN | C24: 事件依据 | D24: 资产证明 | F24: 独立官方资产/产品证明
A25: 21 | B25: Linear发行权限失陷/lUSD | C25: 事件依据 | D25: 资产证明 | E25: https://www.theblock.co/post/252408/linear-finance-reports-attack-that-drained-linear-usd-liquidity-on-pancakeswap-and-ascendex | F25: 第二来源兼资产证明
A26: 22 | B26: Resolv异常铸造/USR | C26: 事件依据 | D26: 资产证明 | F26: 独立资产/官方证明
A27: 23 | B27: StablR未授权增发/USDR·EURR | C27: 事件依据 | D27: 资产证明 | F27: 独立官方资产/产品证明
A28: 24 | B28: Origin重入异常铸币/OUSD | C28: 事件依据 | D28: 资产证明 | F28: 独立官方资产/产品证明
A29: 25 | B29: Haven验证漏洞增发/xUSD | C29: 事件依据 | D29: 资产证明 | E29: https://havenprotocol.org/2021/07/16/hard-fork-rollback/ | F29: 第二来源兼资产证明
A30: 26 | B30: SafeDollar奖励计算漏洞/SDO | C30: 事件依据 | D30: 资产证明 | F30: 事件来源兼资产证明
A31: 27 | B31: Cashio伪造抵押铸币/CASH | C31: 事件依据 | D31: 资产证明 | F31: 事件来源兼资产证明
A32: 28 | B32: Nirvana价格曲线操纵/NIRV | C32: 事件依据 | D32: 资产证明 | F32: 事件来源兼资产证明
A33: 29 | B33: Acala奖励配置增发/aUSD | C33: 事件依据 | D33: 资产证明 | F33: 事件来源兼资产证明
A34: 30 | B34: Abracadabra旧价自清算/MIM | C34: 事件依据 | D34: 资产证明 | E34: https://blocksecteam.medium.com/beyond-the-market-risk-a-logic-bug-identified-in-sushiswaps-kashipairmediumriskv1-contract-80ead49d8d6d | F34: 独立资产/官方证明
A35: 31 | B35: Defrost管理员权限攻击/H2O | C35: 事件依据 | D35: 资产证明 | E35: https://www.coindesk.com/business/2022/12/26/defrost-finance-says-hacked-funds-have-been-returned | F35: 第二来源兼资产证明
A36: 32 | B36: Sperax余额迁移漏洞/USDs | C36: 事件依据 | D36: 资产证明 | F36: 独立资产/官方证明
A37: 33 | B37: Platypus提款逻辑漏洞/USP | C37: 事件依据 | D37: 资产证明 | F37: 事件来源兼资产证明
A38: 34 | B38: Kujira抵押估值漏洞/USK | C38: 事件依据 | D38: 资产证明 | F38: 独立资产/官方证明
A39: 35 | B39: DEUS授权参数漏洞/DEI | C39: 事件依据 | D39: 资产证明 | F39: 事件来源兼资产证明
A40: 36 | B40: Palmswap资产捐赠操纵/USDP | C40: 事件依据 | D40: 资产证明 | F40: 事件来源兼资产证明
A41: 37 | B41: Raft舍入异常铸币/R | C41: 事件依据 | D41: 资产证明 | F41: 事件来源兼资产证明
A42: 38 | B42: Abracadabra债务舍入/MIM | C42: 事件依据 | D42: 资产证明 | F42: 独立资产/官方证明
A43: 39 | B43: Prisma迁移重入攻击/mkUSD | C43: 事件依据 | D43: 资产证明 | F43: 事件来源兼资产证明
A44: 40 | B44: Anzen金库精度漏洞/USDz | C44: 事件依据 | D44: 资产证明 | F44: 独立官方资产/产品证明
A45: 41 | B45: Zoth抵押计量错误/ZeUSD | C45: 事件依据 | D45: 资产证明 | F45: Zoth官方ZeUSD代币与合约说明
A46: 42 | B46: USPD初始化代理劫持/USPD | C46: 事件依据 | D46: 资产证明 | F46: 事件来源兼资产证明
A47: 43 | B47: Abracadabra偿付绕过/MIM | C47: 事件依据 | D47: 资产证明 | F47: 独立资产/官方证明
...
